Workbook

Sheet Theory
B1: Mazak VARIAXIS i-500 | CLS → Machine Coordinates | Theory Reference
B3: MACHINE CONFIGURATION | C3: Table-Table | AC configuration | Mazak VARIAXIS i-500
B4: Rotation order | C4: C (inner, closest to workpiece) → A (outer, tilts table)
B5: A-axis | C5: Rotates around X-axis. Positive A = table front tilts UP (toward back of machine). Range: -120° to +30°
B6: C-axis | C6: Rotates around Z-axis. Positive C = CCW when viewed from above. Range: 360° continuous
B7: Home position | C7: A=0, C=0 → table flat, spindle vertical, tool axis = (0, 0, 1)
B8: Pivot point | C8: Px = 0, Py = 0, Pz = 10 mm (above table surface, set in Config sheet)
B9: Tool length | C9: Ignored — CLS is gauge point
B10: WHAT CLS PROVIDES
B11: x, y, z | C11: Tool tip position in WORKPIECE coordinates (mm)
B12: i, j, k | C12: Tool axis unit vector in WORKPIECE coordinates. Vertical tool pointing up from part = (0, 0, 1)
B13: STEP 1 — ROTARY ANGLES | C13: Solve A and C from the tool axis vector (i, j, k)
B14: Forward relationship | C14: When table rotates by A then C, the tool axis in workpiece frame becomes: i = sin(A)·sin(C) j = sin(A)·cos(C) k = cos(A)
B15: Solve A | C15: A = ACOS( k ) gives 0° to 180° Sign of A is determined by sign of j: j ≥ 0 → A_mazak = +ACOS(k) (tilting toward back, positive) j < 0 → A_mazak = −ACOS(k) (tilting toward front, negative)
B16: Solve C | C16: C = ATAN2( i, j ) gives −180° to +180° Note: ATAN2 in Excel = ATAN2(x, y) — Excel argument order is reversed vs math convention. Excel formula: =DEGREES(ATAN2(j, i))
B17: Singularity | C17: When k=1 (vertical tool, A=0): i=j=0, C is undefined. Output C=0 by convention.
B18: STEP 2 — LINEAR AXES | C18: Compute machine XYZ with RTCP OFF and pivot offset
B19: Concept | C19: The table physically rotates — so the post must back-calculate where the spindle must be to keep the tool tip at the correct workpiece point.
B20: Step 2a — Translate to pivot | C20: dx = x − Px dy = y − Py dz = z − Pz
B21: Step 2b — Inverse C rotation | C21: Rotate by −C (undo C table rotation): x1 = dx·cos(C) + dy·sin(C) y1 = −dx·sin(C) + dy·cos(C) z1 = dz
B22: Step 2c — Inverse A rotation | C22: Rotate by −A (undo A table rotation): x2 = x1 y2 = y1·cos(A) + z1·sin(A) z2 = −y1·sin(A) + z1·cos(A)
... B25: VERIFICATION — 90° tilt back | C25: CLS: x=0, y=0, z=0, i=0, j=1, k=0 → A=+90°, C=0° → dx=0, dy=0, dz=−10 → x1=0, y1=0, z1=−10 (C=0, no change) → x2=0, y2=0·cos90+(−10)·sin90=−10, z2=0·(−sin90)+(−10)·cos90=0 → X=0, Y=−10+0=−10, Z=0+10=10 (tool tip displaced as expected by pivot)
B27: RTCP OFF — TWO INTERPRETATIONS
B28: Mode 1: Raw passthrough | C28: The post outputs rotary angles (A, C) and passes XYZ unchanged from CLS. X_m = X_cls, Y_m = Y_cls, Z_m = Z_cls This is what NX Post Builder actually outputs in standard rotary mode. The pivot value in Post Builder has NO effect on G-code in this mode.
B29: Mode 2: Pivot compensation | C29: Full inverse kinematic calculation — the post computes corrected XYZ to account for the physical rotation of the table about the pivot point. Required only if the controller has NO built-in RTCP/TCPM (rare on modern machines). Useful for: verification, collision checking, understanding physical axis travel.
B30: Why pivot in Post Builder has no effect | C30: NX's kinematic solver uses pivot only for simulation display. RTCP ON → controller handles pivot internally (its own parameter, not from post). RTCP OFF → post outputs raw angles + raw XYZ, no compensation applied. Either way, the pivot value entered in Post Builder does not appear in G-code.
B31: DMG DMU 65 changes vs Mazak | C31: Same AC table-table kinematics and same math. Only Config sheet changes: • A-axis max: +30° (Mazak) → +120° (DMU 65) • Py pivot: 0 (Mazak example) → +70 mm (DMU 65) • Pz pivot: 10 mm (Mazak example) → +70 mm (DMU 65) All formulas in Calculator sheet are unchanged.
B33: BC TABLE-TABLE KINEMATICS
B34: Machine example | C34: DMG DMU 50 (3rd gen) | B-axis: -35° to +110° | C-axis: 360° B rotates around Y-axis. C rotates around Z-axis (inner).
B35: Forward relationship | C35: When table rotates by B (outer) then C (inner), tool axis in workpiece frame: i = sin(B) · cos(C) j = -sin(B) · sin(C) k = cos(B) Derived from: R_C^T · R_B^T · (0,0,1)
B36: Solve B | C36: B = ACOS(k) → sign from sign of i: i ≥ 0 → B positive (tilt toward +X) i < 0 → B negative Singularity: i=0 and j=0 → B=0, C=0
B37: Solve C | C37: C = atan2(−j, i) Excel formula: =DEGREES(ATAN2(I_cell, −J_cell)) Note: Excel ATAN2(x,y) = atan(y/x), so arguments are (i, −j)
B38: BC vs AC — key difference | C38: AC: B-rotation is around X → Y and Z mix BC: B-rotation is around Y → X and Z mix, Y is decoupled AC inverse rotation (X-axis): Xm = x1 + Px Ym = y1·cos(A) + z1·sin(A) + Py Zm = −y1·sin(A) + z1·cos(A) + Pz BC inverse rotation (Y-axis): Xm = x1·cos(B) + z1·sin(B) + Px Ym = y1 + Py Zm = −x1·sin(B) + z1·cos(B) + Pz
B39: Verification — vertical tool | C39: CLS: i=0,j=0,k=1 → B=0, C=0 dx=0, dy=0, dz=−Pz x1=0 (C=0), y1=0, z1=−Pz Xm = 0·cos0+(−Pz)·sin0+Px = 0+Px ✓ Ym = 0+Py ✓ Zm = 0+(−Pz)·cos0+Pz = −Pz+Pz = 0 ✓
B40: Verification — B=+90° tilt | C40: CLS: i=1,j=0,k=0 → B=90°, C=0° dx=0, dy=0, dz=−Pz x1=0, y1=0, z1=−Pz (C=0, no change) Xm = 0·cos90+(−Pz)·sin90+Px = −Pz+Px Ym = 0+Py ✓ (Y unchanged for BC) Zm = −0·sin90+(−Pz)·cos90+Pz = 0+Pz = Pz (pivot height remains) ✓
B42: BC HEAD-TABLE KINEMATICS
B43: Machine example | C43: Mazak Vortex i-630V (also INTEGREX i-630V) | B-axis (spindle head swivel): -30° to +120° | C-axis (rotary table): 360° B rotates around Y-axis. C rotates the WORKPIECE around Z-axis.
B44: Fundamental difference from table-table | C44: Table-table: BOTH rotations act on the workpiece. Tool axis is fixed in machine frame. Head-table: B rotates the SPINDLE (tool axis changes in machine frame). C rotates the TABLE (workpiece changes in machine frame). These are INDEPENDENT kinematic chains — B and C are solved separately.
B45: Solve B from (i, j, k) | C45: B rotates the spindle around Y-axis. At B=0, spindle points down = (0,0,1) in workpiece CLS. Forward: i = sin(B), j = 0, k = cos(B) → B = ATAN2(i, k) [full quadrant, no sign ambiguity needed] → j should always = 0 for this machine. If j≠0 in your CLS, verify your post setup. Excel: =DEGREES(ATAN2(K_cell, I_cell)) [Excel ATAN2(x,y)=atan(y/x) → use ATAN2(k,i)]
B46: Solve C | C46: C rotates the TABLE — it is an INDEPENDENT positional axis. C is NOT derived from (i,j,k) because it does not affect the tool axis direction. In practice: C is programmed explicitly in the G-code (e.g. C0., C90., C180.) or driven by the CAM system as a separate rotary positioning move. → Calculator defaults C=0. Manually enter C in column K to simulate other positions.
...

Sheet Config
B1: Machine Configuration & Parameters — 5-Axis CLS Calculator
B3: MACHINE SELECTOR
B4: Selected Machine | C4: 1 | D4: (1 to 7)
B5: Machine 1 | C5: Mazak VARIAXIS i-500 | D5: AC-TT | E5: Table-Table | A: -120/+30° | C: 360° unlimited
B6: Machine 2 | C6: DMG DMU 65 monoBLOCK | D6: AC-TT | E6: Table-Table | A: ±120° | C: 360° unlimited
B7: Machine 3 | C7: DMG DMU 50 (3rd gen) | D7: BC-TT | E7: Table-Table | B: -5/+110° | C: 360° unlimited
B8: Machine 4 | C8: Mazak Vortex i-630V | D8: BC-HT | E8: Head-Table | B: -30/+120° | C: 360° unlimited
B9: Machine 5 | C9: Hartford Aero-426 | D9: BC-HH | E9: Head-Head | B: ±110° | C: ±360°
B10: Machine 6 | C10: DMG DMC 80U duoBLOCK | D10: BC-NUT | E10: Head-Table 45° Nutating | B: -30/+180° | C: 360° unlimited
B11: Machine 7 | C11: DMG DMU 60 eVo | D11: BC-ARB | E11: Table-Table Arbitrary B-axis | B: -5/+180° | C: 360° unlimited
B13: B-AXIS UNIT VECTOR (Machine 7 — DMU 60 eVo arbitrary B-axis)
B14: Component | C14: Value | D14: Note
B15: nx (X component) | C15: -0.584825 | D15: Angle from +X axis = 54.2°
B16: ny (Y component) | C16: 0.573576 | D16: Angle from +Y axis = 55.0°
B17: nz (Z component) | C17: -0.573576 | D17: Angle from +Z axis = 125.0°
B19: DERIVED CONSTANTS (auto-computed from nx, ny, nz above — do not edit)
B20: nz² | C20: =C17*C17 -> 0.32898943 | D20: 0.328931 (nz squared)
B21: 1 − nz² | C21: =1-C17*C17 -> 0.67101057 | D21: 0.671069 (1 minus nz squared)
B22: nx·nz | C22: =C15*C17 -> 0.33544158 | D22: 0.335470 (nx times nz)
B23: ny·nz | C23: =C16*C17 -> -0.32898943 | D23: -0.328931 (ny times nz)
B25: PIVOT POINT (per machine — edit values below)
B26: Parameter | C26: M1 Mazak i-500 | D26: M2 DMU65 | E26: M3 DMU50 | F26: M4 Vortex | G26: M5 Hartford | H26: M6 DMC80U | I26: M7 DMU60eVo
B27: Px (mm) | C27: 0 | D27: 0 | E27: 0 | F27: 0 | G27: 0 | H27: 0 | I27: 0
B28: Py (mm) | C28: 0 | D28: 70 | E28: 0 | F28: 0 | G28: 0 | H28: 0 | I28: 0
B29: Pz (mm) | C29: 0 | D29: 70 | E29: 10 | F29: 0 | G29: 0 | H29: 0 | I29: 0
B30: Pb (mm) Head pivot (M4-7) | C30: 0 | D30: 0 | E30: 0 | F30: 100 | G30: 150 | H30: 120 | I30: 0
B32: AXIS LIMITS (per machine — edit values below)
B33: Parameter | C33: M1 Mazak i-500 | D33: M2 DMU65 | E33: M3 DMU50 | F33: M4 Vortex | G33: M5 Hartford | H33: M6 DMC80U | I33: M7 DMU60eVo
B34: 1st Rotary min (A or B°) | C34: -120 | D34: -120 | E34: -5 | F34: -30 | G34: -110 | H34: -30 | I34: -5
B35: 1st Rotary max (A or B°) | C35: 30 | D35: 120 | E35: 110 | F35: 120 | G35: 110 | H35: 180 | I35: 180
B36: C-axis min (°) | C36: -999999 | D36: -999999 | E36: -999999 | F36: -999999 | G36: -360 | H36: -999999 | I36: -999999
B37: C-axis max (°) | C37: 999999 | D37: 999999 | E37: 999999 | F37: 999999 | G37: 360 | H37: -999999 | I37: 999999
B39: C is unlimited continuous — set to ±999999 to effectively disable limit check. Adjust to your actual control soft limits if known.
B41: KINEMATIC TYPE SUMMARY
B42: Machine 1 | C42: AC-TT | D42: Table-Table: A (tilt, around X) + C (rotate, around Z). Workpiece rotates.
B43: Machine 2 | C43: AC-TT | D43: Table-Table: A (tilt, around X) + C (rotate, around Z). Workpiece rotates.
B44: Machine 3 | C44: BC-TT | D44: Table-Table: B (tilt, around Y) + C (rotate, around Z). Workpiece rotates.
B45: Machine 4 | C45: BC-HT | D45: Head-Table: B swivels spindle (around Y). C rotates table independently.
B46: Machine 5 | C46: BC-HH | D46: Head-Head: C rotates head (outer). B tilts spindle (inner). Workpiece FIXED.
B47: Machine 6 | C47: BC-NUT | D47: Head-Table 45° Nutating: B-axis tilted 45° from Z. Rodrigues rotation.
...

Sheet Calculator
B1: CLS → Machine Coordinates Calculator
B2: =IF(Config!$C$4=1,"▶ M1: Mazak VARIAXIS i-500 | AC Table-Table | ",IF(Config!$C$4=2,"▶ M2: DMG DMU 65 | AC Table-Table | ",IF(Config!$C$4=3,"▶ M3: DMG DMU 50 | BC Table-Table | ",IF(Config!$C$4=4,"▶ M4: Mazak Vortex i-630V | BC Head-Table | ",IF(Config!$C$4=5,"▶ M5: Hartford Aero-426 | BC Head-Head | ",IF(Config!$C$4=6,"▶ M6: DMG DMC 80U duoBLOCK | BC Nutating 45° | ","▶ M7: DMG DMU 60 eVo | BC Arbitrary B-axis Table-Table | "))))))&IF(Config!$C$51=1,"Mode 1: Raw passthrough (G-code output)","Mode 2: Pivot-compensated") -> ▶ M1: Mazak VARIAXIS i-500 | AC Table-Table | Mode 2: Pivot-compensated
B3: CLS INPUT (Workpiece Coordinates) | K3: ROTARY ANGLES | N3: MACHINE POSITION (mm) | R3: LIMIT CHECK | U3: MACHINE POSITION CALCULATIONS | AA3: 2ND SOLUTION — ROTARY ANGLES | AD3: 2ND MACHINE POSITION (mm) | AH3: 2ND LIMIT CHECK
B4: # | C4: OPERATION NAME | D4: X (mm) | E4: Y (mm) | F4: Z (mm) | G4: I | H4: J | I4: K | K4: B or A (deg) | L4: C (deg) | N4: X_m (mm) | O4: Y_m (mm) | P4: Z_m (mm) | R4: 1st Rot limit? | S4: 1st C limit? | U4: HELPERS-1 | V4: HELPERS-2 | W4: HELPERS-3 | X4: HELPERS-4 | Y4: HELPERS-5 | AA4: 2nd Rot (deg) | AB4: 2nd C (deg) | AD4: 2nd X_m (mm) | AE4: 2nd Y_m (mm) | AF4: 2nd Z_m (mm) | AH4: 2nd Rot limit? | AI4: 2nd C limit?
B5: 1 | D5: 0 | E5: 0 | F5: 0 | G5: 0 | H5: 0 | I5: 1 | K5: =IF( I5="", "", IF( Config!$C$4<=2, IF( AND(G5=0,H5=0), 0, IF( H5>=0, DEGREES(ACOS(I5)), -DEGREES(ACOS(I5)) ) ), IF( Config!$C$4=3, IF( AND(G5=0,H5=0), 0, IF( G5>=0, DEGREES(ACOS(I5)), -DEGREES(ACOS(I5)) ) ), IF( Config!$C$4=4, IF( AND(G5=0,H5=0), 0, DEGREES(ATAN2(I5,G5)) ), IF( Config!$C$4=5, IF( AND(G5=0,H5=0), 0, DEGREES(ACOS(I5)) ), IF( Config!$C$4=6, IF( AND(G5=0,H5=0), 0, IF( G5>=0, DEGREES(ACOS(2*I5-1)), -DEGREES(ACOS(2*I5-1)) ) ), IF( AND(G5=0,H5=0), 0, IF( ((G5*Config!$C$16-H5*Config!$C$15))<=0, DEGREES( ACOS( MAX( -1, MIN( 1, (I5-Config!$C$20)/Config!$C$21 ) ) ) ), -DEGREES( ACOS( MAX( -1, MIN( 1, (I5-Config!$C$20)/Config!$C$21 ) ) ) ) ) ) ) ) ) ) ) ) -> 0 | L5: =IF( I5="", "", IF( Config!$C$4<=2, IF( AND(G5=0,H5=0), 0, DEGREES(ATAN2(H5,G5)) ), IF( Config!$C$4=3, IF( AND(G5=0,H5=0), 0, DEGREES(ATAN2(G5,-H5)) ), IF( Config!$C$4=4, 0, IF( Config!$C$4=5, IF( AND(G5=0,H5=0), 0, DEGREES(ATAN2(H5,G5)) ), IF( Config!$C$4=6, IF( AND(G5=0,H5=0), 0, DEGREES(ATAN2(H5,G5)) ), 0 ) ) ) ) ) ) -> 0 | N5: =IF(I5="","", IF(Config!$C$51=1, D5, IF(U5<=2, (D5 - V5)*COS(RADIANS(L5)) + (E5 - W5)*SIN(RADIANS(L5)) + V5, IF(U5=3, ((D5 - V5)*COS(RADIANS(L5)) + (E5 - W5)*SIN(RADIANS(L5)))*COS(RADIANS(K5)) + (F5 - X5)*SIN(RADIANS(K5)) + V5, IF(U5=4, (D5*COS(RADIANS(L5)) + E5*SIN(RADIANS(L5)) + V5) + Y5*SIN(RADIANS(K5)), IF(U5=5, D5 + Y5*SIN(RADIANS(K5))*COS(RADIANS(L5)), IF(U5=6, (D5*COS(RADIANS(L5)) + E5*SIN(RADIANS(L5)) + V5) + Y5*SIN(RADIANS(K5))*SIN(RADIANS(Config!$H$18)), COS(RADIANS(K5)) * (((D5 - V5)*COS(RADIANS(L5)) + (E5 - W5)*SIN(RADIANS(L5)))) + SIN(RADIANS(K5)) * ( Config!$C$16*(F5 - X5) - Config!$C$17*(-(D5 - V5)*SIN(RADIANS(L5)) + (E5 - W5)*COS(RADIANS(L5))) ) + (1 - COS(RADIANS(K5))) * ( ((D5 - V5)*COS(RADIANS(L5)) + (E5 - W5)*SIN(RADIANS(L5)))*Config!$C$15 + (-(D5 - V5)*SIN(RADIANS(L5)) + (E5 - W5)*COS(RADIANS(L5)))*Config!$C$16 + (F5 - X5)*Config!$C$17 ) * Config!$C$15 + V5 ) ) ) ) ) ) ) -> 0 | O5: =IF(I5="","", IF(Config!$C$51=1, E5, IF(U5 <= 2, (-(D5 - V5) * SIN(RADIANS(L5)) + (E5 - W5) * COS(RADIANS(L5))) * COS(RADIANS(K5)) + (F5 - X5) * SIN(RADIANS(K5)) + W5, IF(U5 = 3, (-(D5 - V5) * SIN(RADIANS(L5)) + (E5 - W5) * COS(RADIANS(L5))) + W5, IF(U5 = 4, -(D5) * SIN(RADIANS(L5)) + (E5) * COS(RADIANS(L5)) + W5, IF(U5 = 5, E5 + Y5 * SIN(RADIANS(K5)) * SIN(RADIANS(L5)), IF(U5 = 6, (-(D5) * SIN(RADIANS(L5)) + (E5) * COS(RADIANS(L5)) + W5) + Y5 * (1 - COS(RADIANS(K5))) * SIN(RADIANS(Config!$H$18)) * COS(RADIANS(Config!$H$18)), COS(RADIANS(K5)) * (-(D5 - V5) * SIN(RADIANS(L5)) + (E5 - W5) * COS(RADIANS(L5))) + SIN(RADIANS(K5)) * ( Config!$C$17 * ((D5 - V5) * COS(RADIANS(L5)) + (E5 - W5) * SIN(RADIANS(L5))) - Config!$C$15 * (F5 - X5) ) + (1 - COS(RADIANS(K5))) * ( ((D5 - V5) * COS(RADIANS(L5)) + (E5 - W5) * SIN(RADIANS(L5))) * Config!$C$15 + (-(D5 - V5) * SIN(RADIANS(L5)) + (E5 - W5) * COS(RADIANS(L5))) * Config!$C$16 + (F5 - X5) * Config!$C$17 ) * Config!$C$16 + W5 ) ) ) ) ) ) ) -> 0 | P5: =IF(I5="","", IF(Config!$C$51=1, F5, IF(U5 <= 2, -((-(D5 - V5) * SIN(RADIANS(L5)) + (E5 - W5) * COS(RADIANS(L5)))) * SIN(RADIANS(K5)) + (F5 - X5) * COS(RADIANS(K5)) + X5, IF(U5 = 3, -(((D5 - V5) * COS(RADIANS(L5)) + (E5 - W5) * SIN(RADIANS(L5)))) * SIN(RADIANS(K5)) + (F5 - X5) * COS(RADIANS(K5)) + X5, IF(U5 = 4, (F5 + X5) - Y5 * (1 - COS(RADIANS(K5))), IF(U5 = 5, F5 - Y5 * (1 - COS(RADIANS(K5))), IF(U5 = 6, (F5 + X5) - Y5 * SIN(RADIANS(Config!$H$18)) * SIN(RADIANS(Config!$H$18)) * (1 - COS(RADIANS(K5))), COS(RADIANS(K5)) * (F5 - X5) + SIN(RADIANS(K5)) * ( Config!$C$15 * (-(D5 - V5) * SIN(RADIANS(L5)) + (E5 - W5) * COS(RADIANS(L5))) - Config!$C$16 * ((D5 - V5) * COS(RADIANS(L5)) + (E5 - W5) * SIN(RADIANS(L5))) ) + (1 - COS(RADIANS(K5))) * ( ((D5 - V5) * COS(RADIANS(L5)) + (E5 - W5) * SIN(RADIANS(L5))) * Config!$C$15 + (-(D5 - V5) * SIN(RADIANS(L5)) + (E5 - W5) * COS(RADIANS(L5))) * Config!$C$16 + (F5 - X5) * Config!$C$17 ) * Config!$C$17 + X5 ) ) ) ) ) ) ) -> 0 | R5: =IF(I5="","", IF(OR( K5 < IF(Config!$C$4=1,Config!$C$34, IF(Config!$C$4=2,Config!$D$34, IF(Config!$C$4=3,Config!$E$34, IF(Config!$C$4=4,Config!$F$34, IF(Config!$C$4=5,Config!$G$34, IF(Config!$C$4=6,Config!$H$34,Config!$I$34) ) ) ) ) ), K5 > IF(Config!$C$4=1,Config!$C$35, IF(Config!$C$4=2,Config!$D$35, IF(Config!$C$4=3,Config!$E$35, IF(Config!$C$4=4,Config!$F$35, IF(Config!$C$4=5,Config!$G$35, IF(Config!$C$4=6,Config!$H$35,Config!$I$35) ) ) ) ) ) ), "⚠ OUT OF RANGE", "OK" ) ) -> OK | S5: =IF(I5="","", IF(OR( L5 < IF(Config!$C$4=1,Config!$C$36, IF(Config!$C$4=2,Config!$D$36, IF(Config!$C$4=3,Config!$E$36, IF(Config!$C$4=4,Config!$F$36, IF(Config!$C$4=5,Config!$G$36, IF(Config!$C$4=6,Config!$H$36,Config!$I$36) ) ) ) ) ), L5 > IF(Config!$C$4=1,Config!$C$37, IF(Config!$C$4=2,Config!$D$37, IF(Config!$C$4=3,Config!$E$37, IF(Config!$C$4=4,Config!$F$37, IF(Config!$C$4=5,Config!$G$37, IF(Config!$C$4=6,Config!$H$37,Config!$I$37) ) ) ) ) ) ), "⚠ OUT OF RANGE", "OK" ) ) -> OK | U5: =Config!$C$4 -> 1 | V5: =IF(U5=1, Config!$C$27, IF(U5=2, Config!$D$27, IF(U5=3, Config!$E$27, IF(U5=4, Config!$F$27, IF(U5=5, Config!$G$27, IF(U5=6, Config!$H$27, Config!$I$27 ) ) ) ) ) ) -> 0 | W5: =IF(U5=1, Config!$C$28, IF(U5=2, Config!$D$28, IF(U5=3, Config!$E$28, IF(U5=4, Config!$F$28, IF(U5=5, Config!$G$28, IF(U5=6, Config!$H$28, Config!$I$28 ) ) ) ) ) ) -> 0 | X5: =IF(U5=1, Config!$C$29, IF(U5=2, Config!$D$29, IF(U5=3, Config!$E$29, IF(U5=4, Config!$F$29, IF(U5=5, Config!$G$29, IF(U5=6, Config!$H$29, Config!$I$29 ) ) ) ) ) ) -> 0 | Y5: =IF(U5=1, Config!$C$30, IF(U5=2, Config!$D$30, IF(U5=3, Config!$E$30, IF(U5=4, Config!$F$30, IF(U5=5, Config!$G$30, IF(U5=6, Config!$H$30, Config!$I$30 ) ) ) ) ) ) -> 0 | AA5: =IF(I5="","", IF(U5<=2, IF(AND(G5=0,H5=0), 0, -K5), IF(U5=3, IF(AND(G5=0,H5=0), 0, -K5), IF(U5=4, IF(K5>=0, 180-K5, -180-K5), IF(U5=5, "N/A", IF(U5=6, IF(AND(G5=0,H5=0), 0, -K5), "N/A" ) ) ) ) ) ) -> 0 | AB5: =IF(I5="","", IF(U5<=2, IF(AND(G5=0,H5=0), 0, IF(L5<=0, L5+180, L5-180) ), IF(U5=3, IF(AND(G5=0,H5=0), 0, IF(L5<=0, L5+180, L5-180) ), IF(U5=4, L5, IF(U5=5, "N/A", IF(U5=6, IF(AND(G5=0,H5=0), 0, IF(L5<=0, L5+180, L5-180) ), "N/A" ) ) ) ) ) ) -> 0 | AD5: =IF(I5="","", IF(Config!$C$51=1, D5, IF(U5<=2, (D5 - V5)*COS(RADIANS(AB5)) + (E5 - W5)*SIN(RADIANS(AB5)) + V5, IF(U5=3, ((D5 - V5)*COS(RADIANS(AB5)) + (E5 - W5)*SIN(RADIANS(AB5)))*COS(RADIANS(AA5)) + (F5 - X5)*SIN(RADIANS(AA5)) + V5, IF(U5=4, (D5*COS(RADIANS(AB5)) + E5*SIN(RADIANS(AB5)) + V5) + Y5*SIN(RADIANS(AA5)), IF(U5=5, D5 + Y5*SIN(RADIANS(AA5))*COS(RADIANS(AB5)), IF(U5=6, (D5*COS(RADIANS(AB5)) + E5*SIN(RADIANS(AB5)) + V5) + Y5*SIN(RADIANS(AA5))*SIN(RADIANS(Config!$H$18)), COS(RADIANS(AA5)) * (((D5 - V5)*COS(RADIANS(AB5)) + (E5 - W5)*SIN(RADIANS(AB5)))) + SIN(RADIANS(AA5)) * ( Config!$C$16*(F5 - X5) - Config!$C$17*(-(D5 - V5)*SIN(RADIANS(AB5)) + (E5 - W5)*COS(RADIANS(AB5))) ) + (1 - COS(RADIANS(AA5))) * ( ((D5 - V5)*COS(RADIANS(AB5)) + (E5 - W5)*SIN(RADIANS(AB5)))*Config!$C$15 + (-(D5 - V5)*SIN(RADIANS(AB5)) + (E5 - W5)*COS(RADIANS(AB5)))*Config!$C$16 + (F5 - X5)*Config!$C$17 ) * Config!$C$15 + V5 ) ) ) ) ) ) ) -> 0 | AE5: =IF(I5="","", IF(Config!$C$51=1, E5, IF(U5 <= 2, (-(D5 - V5) * SIN(RADIANS(AB5)) + (E5 - W5) * COS(RADIANS(AB5))) * COS(RADIANS(AA5)) + (F5 - X5) * SIN(RADIANS(AA5)) + W5, IF(U5 = 3, (-(D5 - V5) * SIN(RADIANS(AB5)) + (E5 - W5) * COS(RADIANS(AB5))) + W5, IF(U5 = 4, -(D5) * SIN(RADIANS(AB5)) + (E5) * COS(RADIANS(AB5)) + W5, IF(U5 = 5, E5 + Y5 * SIN(RADIANS(AA5)) * SIN(RADIANS(AB5)), IF(U5 = 6, (-(D5) * SIN(RADIANS(AB5)) + (E5) * COS(RADIANS(AB5)) + W5) + Y5 * (1 - COS(RADIANS(AA5))) * SIN(RADIANS(Config!$H$18)) * COS(RADIANS(Config!$H$18)), COS(RADIANS(AA5)) * (-(D5 - V5) * SIN(RADIANS(AB5)) + (E5 - W5) * COS(RADIANS(AB5))) + SIN(RADIANS(AA5)) * ( Config!$C$17 * ((D5 - V5) * COS(RADIANS(AB5)) + (E5 - W5) * SIN(RADIANS(AB5))) - Config!$C$15 * (F5 - X5) ) + (1 - COS(RADIANS(AA5))) * ( ((D5 - V5) * COS(RADIANS(AB5)) + (E5 - W5) * SIN(RADIANS(AB5))) * Config!$C$15 + (-(D5 - V5) * SIN(RADIANS(AB5)) + (E5 - W5) * COS(RADIANS(AB5))) * Config!$C$16 + (F5 - X5) * Config!$C$17 ) * Config!$C$16 + W5 ) ) ) ) ) ) ) -> 0 | AF5: =IF(I5="","", IF(Config!$C$51=1, F5, IF(U5 <= 2, -((-(D5 - V5) * SIN(RADIANS(AB5)) + (E5 - W5) * COS(RADIANS(AB5)))) * SIN(RADIANS(AA5)) + (F5 - X5) * COS(RADIANS(AA5)) + X5, IF(U5 = 3, -(((D5 - V5) * COS(RADIANS(AB5)) + (E5 - W5) * SIN(RADIANS(AB5)))) * SIN(RADIANS(AA5)) + (F5 - X5) * COS(RADIANS(AA5)) + X5, IF(U5 = 4, (F5 + X5) - Y5 * (1 - COS(RADIANS(AA5))), IF(U5 = 5, F5 - Y5 * (1 - COS(RADIANS(AA5))), IF(U5 = 6, (F5 + X5) - Y5 * SIN(RADIANS(Config!$H$18)) * SIN(RADIANS(Config!$H$18)) * (1 - COS(RADIANS(AA5))), COS(RADIANS(AA5)) * (F5 - X5) + SIN(RADIANS(AA5)) * ( Config!$C$15 * (-(D5 - V5) * SIN(RADIANS(AB5)) + (E5 - W5) * COS(RADIANS(AB5))) - Config!$C$16 * ((D5 - V5) * COS(RADIANS(AB5)) + (E5 - W5) * SIN(RADIANS(AB5))) ) + (1 - COS(RADIANS(AA5))) * ( ((D5 - V5) * COS(RADIANS(AB5)) + (E5 - W5) * SIN(RADIANS(AB5))) * Config!$C$15 + (-(D5 - V5) * SIN(RADIANS(AB5)) + (E5 - W5) * COS(RADIANS(AB5))) * Config!$C$16 + (F5 - X5) * Config!$C$17 ) * Config!$C$17 + X5 ) ) ) ) ) ) ) -> 0 | AH5: =IF(I5="","", IF(OR(AA5="N/A", AA5=""), "N/A", IF(OR( AA5 < IF(Config!$C$4=1,Config!$C$34, IF(Config!$C$4=2,Config!$D$34, IF(Config!$C$4=3,Config!$E$34, IF(Config!$C$4=4,Config!$F$34, IF(Config!$C$4=5,Config!$G$34, IF(Config!$C$4=6,Config!$H$34,Config!$I$34) ) ) ) ) ), AA5 > IF(Config!$C$4=1,Config!$C$35, IF(Config!$C$4=2,Config!$D$35, IF(Config!$C$4=3,Config!$E$35, IF(Config!$C$4=4,Config!$F$35, IF(Config!$C$4=5,Config!$G$35, IF(Config!$C$4=6,Config!$H$35,Config!$I$35) ) ) ) ) ) ), "⚠ OUT OF RANGE", "OK" ) ) ) -> OK | AI5: =IF(I5="","", IF(OR(AB5="N/A", AB5=""), "N/A", IF(OR( AB5 < IF(Config!$C$4=1,Config!$C$36, IF(Config!$C$4=2,Config!$D$36, IF(Config!$C$4=3,Config!$E$36, IF(Config!$C$4=4,Config!$F$36, IF(Config!$C$4=5,Config!$G$36, IF(Config!$C$4=6,Config!$H$36,Config!$I$36) ) ) ) ) ), AB5 > IF(Config!$C$4=1,Config!$C$37, IF(Config!$C$4=2,Config!$D$37, IF(Config!$C$4=3,Config!$E$37, IF(Config!$C$4=4,Config!$F$37, IF(Config!$C$4=5,Config!$G$37, IF(Config!$C$4=6,Config!$H$37,Config!$I$37) ) ) ) ) ) ), "⚠ OUT OF RANGE", "OK" ) ) ) -> OK
B6: 2 | D6: 50 | E6: 0 | F6: 0 | G6: 0 | H6: 0 | I6: 1 | K6: =IF( I6="", "", IF( Config!$C$4<=2, IF( AND(G6=0,H6=0), 0, IF( H6>=0, DEGREES(ACOS(I6)), -DEGREES(ACOS(I6)) ) ), IF( Config!$C$4=3, IF( AND(G6=0,H6=0), 0, IF( G6>=0, DEGREES(ACOS(I6)), -DEGREES(ACOS(I6)) ) ), IF( Config!$C$4=4, IF( AND(G6=0,H6=0), 0, DEGREES(ATAN2(I6,G6)) ), IF( Config!$C$4=5, IF( AND(G6=0,H6=0), 0, DEGREES(ACOS(I6)) ), IF( Config!$C$4=6, IF( AND(G6=0,H6=0), 0, IF( G6>=0, DEGREES(ACOS(2*I6-1)), -DEGREES(ACOS(2*I6-1)) ) ), IF( AND(G6=0,H6=0), 0, IF( ((G6*Config!$C$16-H6*Config!$C$15))<=0, DEGREES( ACOS( MAX( -1, MIN( 1, (I6-Config!$C$20)/Config!$C$21 ) ) ) ), -DEGREES( ACOS( MAX( -1, MIN( 1, (I6-Config!$C$20)/Config!$C$21 ) ) ) ) ) ) ) ) ) ) ) ) -> 0 | L6: =IF( I6="", "", IF( Config!$C$4<=2, IF( AND(G6=0,H6=0), 0, DEGREES(ATAN2(H6,G6)) ), IF( Config!$C$4=3, IF( AND(G6=0,H6=0), 0, DEGREES(ATAN2(G6,-H6)) ), IF( Config!$C$4=4, 0, IF( Config!$C$4=5, IF( AND(G6=0,H6=0), 0, DEGREES(ATAN2(H6,G6)) ), IF( Config!$C$4=6, IF( AND(G6=0,H6=0), 0, DEGREES(ATAN2(H6,G6)) ), 0 ) ) ) ) ) ) -> 0 | N6: =IF(I6="","", IF(Config!$C$51=1, D6, IF(U6<=2, (D6 - V6)*COS(RADIANS(L6)) + (E6 - W6)*SIN(RADIANS(L6)) + V6, IF(U6=3, ((D6 - V6)*COS(RADIANS(L6)) + (E6 - W6)*SIN(RADIANS(L6)))*COS(RADIANS(K6)) + (F6 - X6)*SIN(RADIANS(K6)) + V6, IF(U6=4, (D6*COS(RADIANS(L6)) + E6*SIN(RADIANS(L6)) + V6) + Y6*SIN(RADIANS(K6)), IF(U6=5, D6 + Y6*SIN(RADIANS(K6))*COS(RADIANS(L6)), IF(U6=6, (D6*COS(RADIANS(L6)) + E6*SIN(RADIANS(L6)) + V6) + Y6*SIN(RADIANS(K6))*SIN(RADIANS(Config!$H$18)), COS(RADIANS(K6)) * (((D6 - V6)*COS(RADIANS(L6)) + (E6 - W6)*SIN(RADIANS(L6)))) + SIN(RADIANS(K6)) * ( Config!$C$16*(F6 - X6) - Config!$C$17*(-(D6 - V6)*SIN(RADIANS(L6)) + (E6 - W6)*COS(RADIANS(L6))) ) + (1 - COS(RADIANS(K6))) * ( ((D6 - V6)*COS(RADIANS(L6)) + (E6 - W6)*SIN(RADIANS(L6)))*Config!$C$15 + (-(D6 - V6)*SIN(RADIANS(L6)) + (E6 - W6)*COS(RADIANS(L6)))*Config!$C$16 + (F6 - X6)*Config!$C$17 ) * Config!$C$15 + V6 ) ) ) ) ) ) ) -> 50 | O6: =IF(I6="","", IF(Config!$C$51=1, E6, IF(U6 <= 2, (-(D6 - V6) * SIN(RADIANS(L6)) + (E6 - W6) * COS(RADIANS(L6))) * COS(RADIANS(K6)) + (F6 - X6) * SIN(RADIANS(K6)) + W6, IF(U6 = 3, (-(D6 - V6) * SIN(RADIANS(L6)) + (E6 - W6) * COS(RADIANS(L6))) + W6, IF(U6 = 4, -(D6) * SIN(RADIANS(L6)) + (E6) * COS(RADIANS(L6)) + W6, IF(U6 = 5, E6 + Y6 * SIN(RADIANS(K6)) * SIN(RADIANS(L6)), IF(U6 = 6, (-(D6) * SIN(RADIANS(L6)) + (E6) * COS(RADIANS(L6)) + W6) + Y6 * (1 - COS(RADIANS(K6))) * SIN(RADIANS(Config!$H$18)) * COS(RADIANS(Config!$H$18)), COS(RADIANS(K6)) * (-(D6 - V6) * SIN(RADIANS(L6)) + (E6 - W6) * COS(RADIANS(L6))) + SIN(RADIANS(K6)) * ( Config!$C$17 * ((D6 - V6) * COS(RADIANS(L6)) + (E6 - W6) * SIN(RADIANS(L6))) - Config!$C$15 * (F6 - X6) ) + (1 - COS(RADIANS(K6))) * ( ((D6 - V6) * COS(RADIANS(L6)) + (E6 - W6) * SIN(RADIANS(L6))) * Config!$C$15 + (-(D6 - V6) * SIN(RADIANS(L6)) + (E6 - W6) * COS(RADIANS(L6))) * Config!$C$16 + (F6 - X6) * Config!$C$17 ) * Config!$C$16 + W6 ) ) ) ) ) ) ) -> 0 | P6: =IF(I6="","", IF(Config!$C$51=1, F6, IF(U6 <= 2, -((-(D6 - V6) * SIN(RADIANS(L6)) + (E6 - W6) * COS(RADIANS(L6)))) * SIN(RADIANS(K6)) + (F6 - X6) * COS(RADIANS(K6)) + X6, IF(U6 = 3, -(((D6 - V6) * COS(RADIANS(L6)) + (E6 - W6) * SIN(RADIANS(L6)))) * SIN(RADIANS(K6)) + (F6 - X6) * COS(RADIANS(K6)) + X6, IF(U6 = 4, (F6 + X6) - Y6 * (1 - COS(RADIANS(K6))), IF(U6 = 5, F6 - Y6 * (1 - COS(RADIANS(K6))), IF(U6 = 6, (F6 + X6) - Y6 * SIN(RADIANS(Config!$H$18)) * SIN(RADIANS(Config!$H$18)) * (1 - COS(RADIANS(K6))), COS(RADIANS(K6)) * (F6 - X6) + SIN(RADIANS(K6)) * ( Config!$C$15 * (-(D6 - V6) * SIN(RADIANS(L6)) + (E6 - W6) * COS(RADIANS(L6))) - Config!$C$16 * ((D6 - V6) * COS(RADIANS(L6)) + (E6 - W6) * SIN(RADIANS(L6))) ) + (1 - COS(RADIANS(K6))) * ( ((D6 - V6) * COS(RADIANS(L6)) + (E6 - W6) * SIN(RADIANS(L6))) * Config!$C$15 + (-(D6 - V6) * SIN(RADIANS(L6)) + (E6 - W6) * COS(RADIANS(L6))) * Config!$C$16 + (F6 - X6) * Config!$C$17 ) * Config!$C$17 + X6 ) ) ) ) ) ) ) -> 0 | R6: =IF(I6="","", IF(OR( K6 < IF(Config!$C$4=1,Config!$C$34, IF(Config!$C$4=2,Config!$D$34, IF(Config!$C$4=3,Config!$E$34, IF(Config!$C$4=4,Config!$F$34, IF(Config!$C$4=5,Config!$G$34, IF(Config!$C$4=6,Config!$H$34,Config!$I$34) ) ) ) ) ), K6 > IF(Config!$C$4=1,Config!$C$35, IF(Config!$C$4=2,Config!$D$35, IF(Config!$C$4=3,Config!$E$35, IF(Config!$C$4=4,Config!$F$35, IF(Config!$C$4=5,Config!$G$35, IF(Config!$C$4=6,Config!$H$35,Config!$I$35) ) ) ) ) ) ), "⚠ OUT OF RANGE", "OK" ) ) -> OK | S6: =IF(I6="","", IF(OR( L6 < IF(Config!$C$4=1,Config!$C$36, IF(Config!$C$4=2,Config!$D$36, IF(Config!$C$4=3,Config!$E$36, IF(Config!$C$4=4,Config!$F$36, IF(Config!$C$4=5,Config!$G$36, IF(Config!$C$4=6,Config!$H$36,Config!$I$36) ) ) ) ) ), L6 > IF(Config!$C$4=1,Config!$C$37, IF(Config!$C$4=2,Config!$D$37, IF(Config!$C$4=3,Config!$E$37, IF(Config!$C$4=4,Config!$F$37, IF(Config!$C$4=5,Config!$G$37, IF(Config!$C$4=6,Config!$H$37,Config!$I$37) ) ) ) ) ) ), "⚠ OUT OF RANGE", "OK" ) ) -> OK | U6: =Config!$C$4 -> 1 | V6: =IF(U6=1, Config!$C$27, IF(U6=2, Config!$D$27, IF(U6=3, Config!$E$27, IF(U6=4, Config!$F$27, IF(U6=5, Config!$G$27, IF(U6=6, Config!$H$27, Config!$I$27 ) ) ) ) ) ) -> 0 | W6: =IF(U6=1, Config!$C$28, IF(U6=2, Config!$D$28, IF(U6=3, Config!$E$28, IF(U6=4, Config!$F$28, IF(U6=5, Config!$G$28, IF(U6=6, Config!$H$28, Config!$I$28 ) ) ) ) ) ) -> 0 | X6: =IF(U6=1, Config!$C$29, IF(U6=2, Config!$D$29, IF(U6=3, Config!$E$29, IF(U6=4, Config!$F$29, IF(U6=5, Config!$G$29, IF(U6=6, Config!$H$29, Config!$I$29 ) ) ) ) ) ) -> 0 | Y6: =IF(U6=1, Config!$C$30, IF(U6=2, Config!$D$30, IF(U6=3, Config!$E$30, IF(U6=4, Config!$F$30, IF(U6=5, Config!$G$30, IF(U6=6, Config!$H$30, Config!$I$30 ) ) ) ) ) ) -> 0 | AA6: =IF(I6="","", IF(U6<=2, IF(AND(G6=0,H6=0), 0, -K6), IF(U6=3, IF(AND(G6=0,H6=0), 0, -K6), IF(U6=4, IF(K6>=0, 180-K6, -180-K6), IF(U6=5, "N/A", IF(U6=6, IF(AND(G6=0,H6=0), 0, -K6), "N/A" ) ) ) ) ) ) -> 0 | AB6: =IF(I6="","", IF(U6<=2, IF(AND(G6=0,H6=0), 0, IF(L6<=0, L6+180, L6-180) ), IF(U6=3, IF(AND(G6=0,H6=0), 0, IF(L6<=0, L6+180, L6-180) ), IF(U6=4, L6, IF(U6=5, "N/A", IF(U6=6, IF(AND(G6=0,H6=0), 0, IF(L6<=0, L6+180, L6-180) ), "N/A" ) ) ) ) ) ) -> 0 | AD6: =IF(I6="","", IF(Config!$C$51=1, D6, IF(U6<=2, (D6 - V6)*COS(RADIANS(AB6)) + (E6 - W6)*SIN(RADIANS(AB6)) + V6, IF(U6=3, ((D6 - V6)*COS(RADIANS(AB6)) + (E6 - W6)*SIN(RADIANS(AB6)))*COS(RADIANS(AA6)) + (F6 - X6)*SIN(RADIANS(AA6)) + V6, IF(U6=4, (D6*COS(RADIANS(AB6)) + E6*SIN(RADIANS(AB6)) + V6) + Y6*SIN(RADIANS(AA6)), IF(U6=5, D6 + Y6*SIN(RADIANS(AA6))*COS(RADIANS(AB6)), IF(U6=6, (D6*COS(RADIANS(AB6)) + E6*SIN(RADIANS(AB6)) + V6) + Y6*SIN(RADIANS(AA6))*SIN(RADIANS(Config!$H$18)), COS(RADIANS(AA6)) * (((D6 - V6)*COS(RADIANS(AB6)) + (E6 - W6)*SIN(RADIANS(AB6)))) + SIN(RADIANS(AA6)) * ( Config!$C$16*(F6 - X6) - Config!$C$17*(-(D6 - V6)*SIN(RADIANS(AB6)) + (E6 - W6)*COS(RADIANS(AB6))) ) + (1 - COS(RADIANS(AA6))) * ( ((D6 - V6)*COS(RADIANS(AB6)) + (E6 - W6)*SIN(RADIANS(AB6)))*Config!$C$15 + (-(D6 - V6)*SIN(RADIANS(AB6)) + (E6 - W6)*COS(RADIANS(AB6)))*Config!$C$16 + (F6 - X6)*Config!$C$17 ) * Config!$C$15 + V6 ) ) ) ) ) ) ) -> 50 | AE6: =IF(I6="","", IF(Config!$C$51=1, E6, IF(U6 <= 2, (-(D6 - V6) * SIN(RADIANS(AB6)) + (E6 - W6) * COS(RADIANS(AB6))) * COS(RADIANS(AA6)) + (F6 - X6) * SIN(RADIANS(AA6)) + W6, IF(U6 = 3, (-(D6 - V6) * SIN(RADIANS(AB6)) + (E6 - W6) * COS(RADIANS(AB6))) + W6, IF(U6 = 4, -(D6) * SIN(RADIANS(AB6)) + (E6) * COS(RADIANS(AB6)) + W6, IF(U6 = 5, E6 + Y6 * SIN(RADIANS(AA6)) * SIN(RADIANS(AB6)), IF(U6 = 6, (-(D6) * SIN(RADIANS(AB6)) + (E6) * COS(RADIANS(AB6)) + W6) + Y6 * (1 - COS(RADIANS(AA6))) * SIN(RADIANS(Config!$H$18)) * COS(RADIANS(Config!$H$18)), COS(RADIANS(AA6)) * (-(D6 - V6) * SIN(RADIANS(AB6)) + (E6 - W6) * COS(RADIANS(AB6))) + SIN(RADIANS(AA6)) * ( Config!$C$17 * ((D6 - V6) * COS(RADIANS(AB6)) + (E6 - W6) * SIN(RADIANS(AB6))) - Config!$C$15 * (F6 - X6) ) + (1 - COS(RADIANS(AA6))) * ( ((D6 - V6) * COS(RADIANS(AB6)) + (E6 - W6) * SIN(RADIANS(AB6))) * Config!$C$15 + (-(D6 - V6) * SIN(RADIANS(AB6)) + (E6 - W6) * COS(RADIANS(AB6))) * Config!$C$16 + (F6 - X6) * Config!$C$17 ) * Config!$C$16 + W6 ) ) ) ) ) ) ) -> 0 | AF6: =IF(I6="","", IF(Config!$C$51=1, F6, IF(U6 <= 2, -((-(D6 - V6) * SIN(RADIANS(AB6)) + (E6 - W6) * COS(RADIANS(AB6)))) * SIN(RADIANS(AA6)) + (F6 - X6) * COS(RADIANS(AA6)) + X6, IF(U6 = 3, -(((D6 - V6) * COS(RADIANS(AB6)) + (E6 - W6) * SIN(RADIANS(AB6)))) * SIN(RADIANS(AA6)) + (F6 - X6) * COS(RADIANS(AA6)) + X6, IF(U6 = 4, (F6 + X6) - Y6 * (1 - COS(RADIANS(AA6))), IF(U6 = 5, F6 - Y6 * (1 - COS(RADIANS(AA6))), IF(U6 = 6, (F6 + X6) - Y6 * SIN(RADIANS(Config!$H$18)) * SIN(RADIANS(Config!$H$18)) * (1 - COS(RADIANS(AA6))), COS(RADIANS(AA6)) * (F6 - X6) + SIN(RADIANS(AA6)) * ( Config!$C$15 * (-(D6 - V6) * SIN(RADIANS(AB6)) + (E6 - W6) * COS(RADIANS(AB6))) - Config!$C$16 * ((D6 - V6) * COS(RADIANS(AB6)) + (E6 - W6) * SIN(RADIANS(AB6))) ) + (1 - COS(RADIANS(AA6))) * ( ((D6 - V6) * COS(RADIANS(AB6)) + (E6 - W6) * SIN(RADIANS(AB6))) * Config!$C$15 + (-(D6 - V6) * SIN(RADIANS(AB6)) + (E6 - W6) * COS(RADIANS(AB6))) * Config!$C$16 + (F6 - X6) * Config!$C$17 ) * Config!$C$17 + X6 ) ) ) ) ) ) ) -> 0 | AH6: =IF(I6="","", IF(OR(AA6="N/A", AA6=""), "N/A", IF(OR( AA6 < IF(Config!$C$4=1,Config!$C$34, IF(Config!$C$4=2,Config!$D$34, IF(Config!$C$4=3,Config!$E$34, IF(Config!$C$4=4,Config!$F$34, IF(Config!$C$4=5,Config!$G$34, IF(Config!$C$4=6,Config!$H$34,Config!$I$34) ) ) ) ) ), AA6 > IF(Config!$C$4=1,Config!$C$35, IF(Config!$C$4=2,Config!$D$35, IF(Config!$C$4=3,Config!$E$35, IF(Config!$C$4=4,Config!$F$35, IF(Config!$C$4=5,Config!$G$35, IF(Config!$C$4=6,Config!$H$35,Config!$I$35) ) ) ) ) ) ), "⚠ OUT OF RANGE", "OK" ) ) ) -> OK | AI6: =IF(I6="","", IF(OR(AB6="N/A", AB6=""), "N/A", IF(OR( AB6 < IF(Config!$C$4=1,Config!$C$36, IF(Config!$C$4=2,Config!$D$36, IF(Config!$C$4=3,Config!$E$36, IF(Config!$C$4=4,Config!$F$36, IF(Config!$C$4=5,Config!$G$36, IF(Config!$C$4=6,Config!$H$36,Config!$I$36) ) ) ) ) ), AB6 > IF(Config!$C$4=1,Config!$C$37, IF(Config!$C$4=2,Config!$D$37, IF(Config!$C$4=3,Config!$E$37, IF(Config!$C$4=4,Config!$F$37, IF(Config!$C$4=5,Config!$G$37, IF(Config!$C$4=6,Config!$H$37,Config!$I$37) ) ) ) ) ) ), "⚠ OUT OF RANGE", "OK" ) ) ) -> OK
B7: 3 | D7: 0 | E7: 0 | F7: 0 | G7: 0.3317 | H7: 0.2484 | I7: 0.9101 | K7: =IF( I7="", "", IF( Config!$C$4<=2, IF( AND(G7=0,H7=0), 0, IF( H7>=0, DEGREES(ACOS(I7)), -DEGREES(ACOS(I7)) ) ), IF( Config!$C$4=3, IF( AND(G7=0,H7=0), 0, IF( G7>=0, DEGREES(ACOS(I7)), -DEGREES(ACOS(I7)) ) ), IF( Config!$C$4=4, IF( AND(G7=0,H7=0), 0, DEGREES(ATAN2(I7,G7)) ), IF( Config!$C$4=5, IF( AND(G7=0,H7=0), 0, DEGREES(ACOS(I7)) ), IF( Config!$C$4=6, IF( AND(G7=0,H7=0), 0, IF( G7>=0, DEGREES(ACOS(2*I7-1)), -DEGREES(ACOS(2*I7-1)) ) ), IF( AND(G7=0,H7=0), 0, IF( ((G7*Config!$C$16-H7*Config!$C$15))<=0, DEGREES( ACOS( MAX( -1, MIN( 1, (I7-Config!$C$20)/Config!$C$21 ) ) ) ), -DEGREES( ACOS( MAX( -1, MIN( 1, (I7-Config!$C$20)/Config!$C$21 ) ) ) ) ) ) ) ) ) ) ) ) -> 24.480826 | L7: =IF( I7="", "", IF( Config!$C$4<=2, IF( AND(G7=0,H7=0), 0, DEGREES(ATAN2(H7,G7)) ), IF( Config!$C$4=3, IF( AND(G7=0,H7=0), 0, DEGREES(ATAN2(G7,-H7)) ), IF( Config!$C$4=4, 0, IF( Config!$C$4=5, IF( AND(G7=0,H7=0), 0, DEGREES(ATAN2(H7,G7)) ), IF( Config!$C$4=6, IF( AND(G7=0,H7=0), 0, DEGREES(ATAN2(H7,G7)) ), 0 ) ) ) ) ) ) -> 53.171581 | N7: =IF(I7="","", IF(Config!$C$51=1, D7, IF(U7<=2, (D7 - V7)*COS(RADIANS(L7)) + (E7 - W7)*SIN(RADIANS(L7)) + V7, IF(U7=3, ((D7 - V7)*COS(RADIANS(L7)) + (E7 - W7)*SIN(RADIANS(L7)))*COS(RADIANS(K7)) + (F7 - X7)*SIN(RADIANS(K7)) + V7, IF(U7=4, (D7*COS(RADIANS(L7)) + E7*SIN(RADIANS(L7)) + V7) + Y7*SIN(RADIANS(K7)), IF(U7=5, D7 + Y7*SIN(RADIANS(K7))*COS(RADIANS(L7)), IF(U7=6, (D7*COS(RADIANS(L7)) + E7*SIN(RADIANS(L7)) + V7) + Y7*SIN(RADIANS(K7))*SIN(RADIANS(Config!$H$18)), COS(RADIANS(K7)) * (((D7 - V7)*COS(RADIANS(L7)) + (E7 - W7)*SIN(RADIANS(L7)))) + SIN(RADIANS(K7)) * ( Config!$C$16*(F7 - X7) - Config!$C$17*(-(D7 - V7)*SIN(RADIANS(L7)) + (E7 - W7)*COS(RADIANS(L7))) ) + (1 - COS(RADIANS(K7))) * ( ((D7 - V7)*COS(RADIANS(L7)) + (E7 - W7)*SIN(RADIANS(L7)))*Config!$C$15 + (-(D7 - V7)*SIN(RADIANS(L7)) + (E7 - W7)*COS(RADIANS(L7)))*Config!$C$16 + (F7 - X7)*Config!$C$17 ) * Config!$C$15 + V7 ) ) ) ) ) ) ) -> 0 | O7: =IF(I7="","", IF(Config!$C$51=1, E7, IF(U7 <= 2, (-(D7 - V7) * SIN(RADIANS(L7)) + (E7 - W7) * COS(RADIANS(L7))) * COS(RADIANS(K7)) + (F7 - X7) * SIN(RADIANS(K7)) + W7, IF(U7 = 3, (-(D7 - V7) * SIN(RADIANS(L7)) + (E7 - W7) * COS(RADIANS(L7))) + W7, IF(U7 = 4, -(D7) * SIN(RADIANS(L7)) + (E7) * COS(RADIANS(L7)) + W7, IF(U7 = 5, E7 + Y7 * SIN(RADIANS(K7)) * SIN(RADIANS(L7)), IF(U7 = 6, (-(D7) * SIN(RADIANS(L7)) + (E7) * COS(RADIANS(L7)) + W7) + Y7 * (1 - COS(RADIANS(K7))) * SIN(RADIANS(Config!$H$18)) * COS(RADIANS(Config!$H$18)), COS(RADIANS(K7)) * (-(D7 - V7) * SIN(RADIANS(L7)) + (E7 - W7) * COS(RADIANS(L7))) + SIN(RADIANS(K7)) * ( Config!$C$17 * ((D7 - V7) * COS(RADIANS(L7)) + (E7 - W7) * SIN(RADIANS(L7))) - Config!$C$15 * (F7 - X7) ) + (1 - COS(RADIANS(K7))) * ( ((D7 - V7) * COS(RADIANS(L7)) + (E7 - W7) * SIN(RADIANS(L7))) * Config!$C$15 + (-(D7 - V7) * SIN(RADIANS(L7)) + (E7 - W7) * COS(RADIANS(L7))) * Config!$C$16 + (F7 - X7) * Config!$C$17 ) * Config!$C$16 + W7 ) ) ) ) ) ) ) -> 0 | P7: =IF(I7="","", IF(Config!$C$51=1, F7, IF(U7 <= 2, -((-(D7 - V7) * SIN(RADIANS(L7)) + (E7 - W7) * COS(RADIANS(L7)))) * SIN(RADIANS(K7)) + (F7 - X7) * COS(RADIANS(K7)) + X7, IF(U7 = 3, -(((D7 - V7) * COS(RADIANS(L7)) + (E7 - W7) * SIN(RADIANS(L7)))) * SIN(RADIANS(K7)) + (F7 - X7) * COS(RADIANS(K7)) + X7, IF(U7 = 4, (F7 + X7) - Y7 * (1 - COS(RADIANS(K7))), IF(U7 = 5, F7 - Y7 * (1 - COS(RADIANS(K7))), IF(U7 = 6, (F7 + X7) - Y7 * SIN(RADIANS(Config!$H$18)) * SIN(RADIANS(Config!$H$18)) * (1 - COS(RADIANS(K7))), COS(RADIANS(K7)) * (F7 - X7) + SIN(RADIANS(K7)) * ( Config!$C$15 * (-(D7 - V7) * SIN(RADIANS(L7)) + (E7 - W7) * COS(RADIANS(L7))) - Config!$C$16 * ((D7 - V7) * COS(RADIANS(L7)) + (E7 - W7) * SIN(RADIANS(L7))) ) + (1 - COS(RADIANS(K7))) * ( ((D7 - V7) * COS(RADIANS(L7)) + (E7 - W7) * SIN(RADIANS(L7))) * Config!$C$15 + (-(D7 - V7) * SIN(RADIANS(L7)) + (E7 - W7) * COS(RADIANS(L7))) * Config!$C$16 + (F7 - X7) * Config!$C$17 ) * Config!$C$17 + X7 ) ) ) ) ) ) ) -> 0 | R7: =IF(I7="","", IF(OR( K7 < IF(Config!$C$4=1,Config!$C$34, IF(Config!$C$4=2,Config!$D$34, IF(Config!$C$4=3,Config!$E$34, IF(Config!$C$4=4,Config!$F$34, IF(Config!$C$4=5,Config!$G$34, IF(Config!$C$4=6,Config!$H$34,Config!$I$34) ) ) ) ) ), K7 > IF(Config!$C$4=1,Config!$C$35, IF(Config!$C$4=2,Config!$D$35, IF(Config!$C$4=3,Config!$E$35, IF(Config!$C$4=4,Config!$F$35, IF(Config!$C$4=5,Config!$G$35, IF(Config!$C$4=6,Config!$H$35,Config!$I$35) ) ) ) ) ) ), "⚠ OUT OF RANGE", "OK" ) ) -> OK | S7: =IF(I7="","", IF(OR( L7 < IF(Config!$C$4=1,Config!$C$36, IF(Config!$C$4=2,Config!$D$36, IF(Config!$C$4=3,Config!$E$36, IF(Config!$C$4=4,Config!$F$36, IF(Config!$C$4=5,Config!$G$36, IF(Config!$C$4=6,Config!$H$36,Config!$I$36) ) ) ) ) ), L7 > IF(Config!$C$4=1,Config!$C$37, IF(Config!$C$4=2,Config!$D$37, IF(Config!$C$4=3,Config!$E$37, IF(Config!$C$4=4,Config!$F$37, IF(Config!$C$4=5,Config!$G$37, IF(Config!$C$4=6,Config!$H$37,Config!$I$37) ) ) ) ) ) ), "⚠ OUT OF RANGE", "OK" ) ) -> OK | U7: =Config!$C$4 -> 1 | V7: =IF(U7=1, Config!$C$27, IF(U7=2, Config!$D$27, IF(U7=3, Config!$E$27, IF(U7=4, Config!$F$27, IF(U7=5, Config!$G$27, IF(U7=6, Config!$H$27, Config!$I$27 ) ) ) ) ) ) -> 0 | W7: =IF(U7=1, Config!$C$28, IF(U7=2, Config!$D$28, IF(U7=3, Config!$E$28, IF(U7=4, Config!$F$28, IF(U7=5, Config!$G$28, IF(U7=6, Config!$H$28, Config!$I$28 ) ) ) ) ) ) -> 0 | X7: =IF(U7=1, Config!$C$29, IF(U7=2, Config!$D$29, IF(U7=3, Config!$E$29, IF(U7=4, Config!$F$29, IF(U7=5, Config!$G$29, IF(U7=6, Config!$H$29, Config!$I$29 ) ) ) ) ) ) -> 0 | Y7: =IF(U7=1, Config!$C$30, IF(U7=2, Config!$D$30, IF(U7=3, Config!$E$30, IF(U7=4, Config!$F$30, IF(U7=5, Config!$G$30, IF(U7=6, Config!$H$30, Config!$I$30 ) ) ) ) ) ) -> 0 | AA7: =IF(I7="","", IF(U7<=2, IF(AND(G7=0,H7=0), 0, -K7), IF(U7=3, IF(AND(G7=0,H7=0), 0, -K7), IF(U7=4, IF(K7>=0, 180-K7, -180-K7), IF(U7=5, "N/A", IF(U7=6, IF(AND(G7=0,H7=0), 0, -K7), "N/A" ) ) ) ) ) ) -> -24.480826 | AB7: =IF(I7="","", IF(U7<=2, IF(AND(G7=0,H7=0), 0, IF(L7<=0, L7+180, L7-180) ), IF(U7=3, IF(AND(G7=0,H7=0), 0, IF(L7<=0, L7+180, L7-180) ), IF(U7=4, L7, IF(U7=5, "N/A", IF(U7=6, IF(AND(G7=0,H7=0), 0, IF(L7<=0, L7+180, L7-180) ), "N/A" ) ) ) ) ) ) -> -126.82842 | AD7: =IF(I7="","", IF(Config!$C$51=1, D7, IF(U7<=2, (D7 - V7)*COS(RADIANS(AB7)) + (E7 - W7)*SIN(RADIANS(AB7)) + V7, IF(U7=3, ((D7 - V7)*COS(RADIANS(AB7)) + (E7 - W7)*SIN(RADIANS(AB7)))*COS(RADIANS(AA7)) + (F7 - X7)*SIN(RADIANS(AA7)) + V7, IF(U7=4, (D7*COS(RADIANS(AB7)) + E7*SIN(RADIANS(AB7)) + V7) + Y7*SIN(RADIANS(AA7)), IF(U7=5, D7 + Y7*SIN(RADIANS(AA7))*COS(RADIANS(AB7)), IF(U7=6, (D7*COS(RADIANS(AB7)) + E7*SIN(RADIANS(AB7)) + V7) + Y7*SIN(RADIANS(AA7))*SIN(RADIANS(Config!$H$18)), COS(RADIANS(AA7)) * (((D7 - V7)*COS(RADIANS(AB7)) + (E7 - W7)*SIN(RADIANS(AB7)))) + SIN(RADIANS(AA7)) * ( Config!$C$16*(F7 - X7) - Config!$C$17*(-(D7 - V7)*SIN(RADIANS(AB7)) + (E7 - W7)*COS(RADIANS(AB7))) ) + (1 - COS(RADIANS(AA7))) * ( ((D7 - V7)*COS(RADIANS(AB7)) + (E7 - W7)*SIN(RADIANS(AB7)))*Config!$C$15 + (-(D7 - V7)*SIN(RADIANS(AB7)) + (E7 - W7)*COS(RADIANS(AB7)))*Config!$C$16 + (F7 - X7)*Config!$C$17 ) * Config!$C$15 + V7 ) ) ) ) ) ) ) -> 0 | AE7: =IF(I7="","", IF(Config!$C$51=1, E7, IF(U7 <= 2, (-(D7 - V7) * SIN(RADIANS(AB7)) + (E7 - W7) * COS(RADIANS(AB7))) * COS(RADIANS(AA7)) + (F7 - X7) * SIN(RADIANS(AA7)) + W7, IF(U7 = 3, (-(D7 - V7) * SIN(RADIANS(AB7)) + (E7 - W7) * COS(RADIANS(AB7))) + W7, IF(U7 = 4, -(D7) * SIN(RADIANS(AB7)) + (E7) * COS(RADIANS(AB7)) + W7, IF(U7 = 5, E7 + Y7 * SIN(RADIANS(AA7)) * SIN(RADIANS(AB7)), IF(U7 = 6, (-(D7) * SIN(RADIANS(AB7)) + (E7) * COS(RADIANS(AB7)) + W7) + Y7 * (1 - COS(RADIANS(AA7))) * SIN(RADIANS(Config!$H$18)) * COS(RADIANS(Config!$H$18)), COS(RADIANS(AA7)) * (-(D7 - V7) * SIN(RADIANS(AB7)) + (E7 - W7) * COS(RADIANS(AB7))) + SIN(RADIANS(AA7)) * ( Config!$C$17 * ((D7 - V7) * COS(RADIANS(AB7)) + (E7 - W7) * SIN(RADIANS(AB7))) - Config!$C$15 * (F7 - X7) ) + (1 - COS(RADIANS(AA7))) * ( ((D7 - V7) * COS(RADIANS(AB7)) + (E7 - W7) * SIN(RADIANS(AB7))) * Config!$C$15 + (-(D7 - V7) * SIN(RADIANS(AB7)) + (E7 - W7) * COS(RADIANS(AB7))) * Config!$C$16 + (F7 - X7) * Config!$C$17 ) * Config!$C$16 + W7 ) ) ) ) ) ) ) -> 0 | AF7: =IF(I7="","", IF(Config!$C$51=1, F7, IF(U7 <= 2, -((-(D7 - V7) * SIN(RADIANS(AB7)) + (E7 - W7) * COS(RADIANS(AB7)))) * SIN(RADIANS(AA7)) + (F7 - X7) * COS(RADIANS(AA7)) + X7, IF(U7 = 3, -(((D7 - V7) * COS(RADIANS(AB7)) + (E7 - W7) * SIN(RADIANS(AB7)))) * SIN(RADIANS(AA7)) + (F7 - X7) * COS(RADIANS(AA7)) + X7, IF(U7 = 4, (F7 + X7) - Y7 * (1 - COS(RADIANS(AA7))), IF(U7 = 5, F7 - Y7 * (1 - COS(RADIANS(AA7))), IF(U7 = 6, (F7 + X7) - Y7 * SIN(RADIANS(Config!$H$18)) * SIN(RADIANS(Config!$H$18)) * (1 - COS(RADIANS(AA7))), COS(RADIANS(AA7)) * (F7 - X7) + SIN(RADIANS(AA7)) * ( Config!$C$15 * (-(D7 - V7) * SIN(RADIANS(AB7)) + (E7 - W7) * COS(RADIANS(AB7))) - Config!$C$16 * ((D7 - V7) * COS(RADIANS(AB7)) + (E7 - W7) * SIN(RADIANS(AB7))) ) + (1 - COS(RADIANS(AA7))) * ( ((D7 - V7) * COS(RADIANS(AB7)) + (E7 - W7) * SIN(RADIANS(AB7))) * Config!$C$15 + (-(D7 - V7) * SIN(RADIANS(AB7)) + (E7 - W7) * COS(RADIANS(AB7))) * Config!$C$16 + (F7 - X7) * Config!$C$17 ) * Config!$C$17 + X7 ) ) ) ) ) ) ) -> 0 | AH7: =IF(I7="","", IF(OR(AA7="N/A", AA7=""), "N/A", IF(OR( AA7 < IF(Config!$C$4=1,Config!$C$34, IF(Config!$C$4=2,Config!$D$34, IF(Config!$C$4=3,Config!$E$34, IF(Config!$C$4=4,Config!$F$34, IF(Config!$C$4=5,Config!$G$34, IF(Config!$C$4=6,Config!$H$34,Config!$I$34) ) ) ) ) ), AA7 > IF(Config!$C$4=1,Config!$C$35, IF(Config!$C$4=2,Config!$D$35, IF(Config!$C$4=3,Config!$E$35, IF(Config!$C$4=4,Config!$F$35, IF(Config!$C$4=5,Config!$G$35, IF(Config!$C$4=6,Config!$H$35,Config!$I$35) ) ) ) ) ) ), "⚠ OUT OF RANGE", "OK" ) ) ) -> OK | AI7: =IF(I7="","", IF(OR(AB7="N/A", AB7=""), "N/A", IF(OR( AB7 < IF(Config!$C$4=1,Config!$C$36, IF(Config!$C$4=2,Config!$D$36, IF(Config!$C$4=3,Config!$E$36, IF(Config!$C$4=4,Config!$F$36, IF(Config!$C$4=5,Config!$G$36, IF(Config!$C$4=6,Config!$H$36,Config!$I$36) ) ) ) ) ), AB7 > IF(Config!$C$4=1,Config!$C$37, IF(Config!$C$4=2,Config!$D$37, IF(Config!$C$4=3,Config!$E$37, IF(Config!$C$4=4,Config!$F$37, IF(Config!$C$4=5,Config!$G$37, IF(Config!$C$4=6,Config!$H$37,Config!$I$37) ) ) ) ) ) ), "⚠ OUT OF RANGE", "OK" ) ) ) -> OK
B8: 4 | D8: 0 | E8: 0 | F8: 0 | G8: -0.0487 | H8: -0.0522 | I8: 0.9974 | K8: =IF( I8="", "", IF( Config!$C$4<=2, IF( AND(G8=0,H8=0), 0, IF( H8>=0, DEGREES(ACOS(I8)), -DEGREES(ACOS(I8)) ) ), IF( Config!$C$4=3, IF( AND(G8=0,H8=0), 0, IF( G8>=0, DEGREES(ACOS(I8)), -DEGREES(ACOS(I8)) ) ), IF( Config!$C$4=4, IF( AND(G8=0,H8=0), 0, DEGREES(ATAN2(I8,G8)) ), IF( Config!$C$4=5, IF( AND(G8=0,H8=0), 0, DEGREES(ACOS(I8)) ), IF( Config!$C$4=6, IF( AND(G8=0,H8=0), 0, IF( G8>=0, DEGREES(ACOS(2*I8-1)), -DEGREES(ACOS(2*I8-1)) ) ), IF( AND(G8=0,H8=0), 0, IF( ((G8*Config!$C$16-H8*Config!$C$15))<=0, DEGREES( ACOS( MAX( -1, MIN( 1, (I8-Config!$C$20)/Config!$C$21 ) ) ) ), -DEGREES( ACOS( MAX( -1, MIN( 1, (I8-Config!$C$20)/Config!$C$21 ) ) ) ) ) ) ) ) ) ) ) ) -> -4.1325531 | L8: =IF( I8="", "", IF( Config!$C$4<=2, IF( AND(G8=0,H8=0), 0, DEGREES(ATAN2(H8,G8)) ), IF( Config!$C$4=3, IF( AND(G8=0,H8=0), 0, DEGREES(ATAN2(G8,-H8)) ), IF( Config!$C$4=4, 0, IF( Config!$C$4=5, IF( AND(G8=0,H8=0), 0, DEGREES(ATAN2(H8,G8)) ), IF( Config!$C$4=6, IF( AND(G8=0,H8=0), 0, DEGREES(ATAN2(H8,G8)) ), 0 ) ) ) ) ) ) -> -136.98667 | N8: =IF(I8="","", IF(Config!$C$51=1, D8, IF(U8<=2, (D8 - V8)*COS(RADIANS(L8)) + (E8 - W8)*SIN(RADIANS(L8)) + V8, IF(U8=3, ((D8 - V8)*COS(RADIANS(L8)) + (E8 - W8)*SIN(RADIANS(L8)))*COS(RADIANS(K8)) + (F8 - X8)*SIN(RADIANS(K8)) + V8, IF(U8=4, (D8*COS(RADIANS(L8)) + E8*SIN(RADIANS(L8)) + V8) + Y8*SIN(RADIANS(K8)), IF(U8=5, D8 + Y8*SIN(RADIANS(K8))*COS(RADIANS(L8)), IF(U8=6, (D8*COS(RADIANS(L8)) + E8*SIN(RADIANS(L8)) + V8) + Y8*SIN(RADIANS(K8))*SIN(RADIANS(Config!$H$18)), COS(RADIANS(K8)) * (((D8 - V8)*COS(RADIANS(L8)) + (E8 - W8)*SIN(RADIANS(L8)))) + SIN(RADIANS(K8)) * ( Config!$C$16*(F8 - X8) - Config!$C$17*(-(D8 - V8)*SIN(RADIANS(L8)) + (E8 - W8)*COS(RADIANS(L8))) ) + (1 - COS(RADIANS(K8))) * ( ((D8 - V8)*COS(RADIANS(L8)) + (E8 - W8)*SIN(RADIANS(L8)))*Config!$C$15 + (-(D8 - V8)*SIN(RADIANS(L8)) + (E8 - W8)*COS(RADIANS(L8)))*Config!$C$16 + (F8 - X8)*Config!$C$17 ) * Config!$C$15 + V8 ) ) ) ) ) ) ) -> 0 | O8: =IF(I8="","", IF(Config!$C$51=1, E8, IF(U8 <= 2, (-(D8 - V8) * SIN(RADIANS(L8)) + (E8 - W8) * COS(RADIANS(L8))) * COS(RADIANS(K8)) + (F8 - X8) * SIN(RADIANS(K8)) + W8, IF(U8 = 3, (-(D8 - V8) * SIN(RADIANS(L8)) + (E8 - W8) * COS(RADIANS(L8))) + W8, IF(U8 = 4, -(D8) * SIN(RADIANS(L8)) + (E8) * COS(RADIANS(L8)) + W8, IF(U8 = 5, E8 + Y8 * SIN(RADIANS(K8)) * SIN(RADIANS(L8)), IF(U8 = 6, (-(D8) * SIN(RADIANS(L8)) + (E8) * COS(RADIANS(L8)) + W8) + Y8 * (1 - COS(RADIANS(K8))) * SIN(RADIANS(Config!$H$18)) * COS(RADIANS(Config!$H$18)), COS(RADIANS(K8)) * (-(D8 - V8) * SIN(RADIANS(L8)) + (E8 - W8) * COS(RADIANS(L8))) + SIN(RADIANS(K8)) * ( Config!$C$17 * ((D8 - V8) * COS(RADIANS(L8)) + (E8 - W8) * SIN(RADIANS(L8))) - Config!$C$15 * (F8 - X8) ) + (1 - COS(RADIANS(K8))) * ( ((D8 - V8) * COS(RADIANS(L8)) + (E8 - W8) * SIN(RADIANS(L8))) * Config!$C$15 + (-(D8 - V8) * SIN(RADIANS(L8)) + (E8 - W8) * COS(RADIANS(L8))) * Config!$C$16 + (F8 - X8) * Config!$C$17 ) * Config!$C$16 + W8 ) ) ) ) ) ) ) -> 0 | P8: =IF(I8="","", IF(Config!$C$51=1, F8, IF(U8 <= 2, -((-(D8 - V8) * SIN(RADIANS(L8)) + (E8 - W8) * COS(RADIANS(L8)))) * SIN(RADIANS(K8)) + (F8 - X8) * COS(RADIANS(K8)) + X8, IF(U8 = 3, -(((D8 - V8) * COS(RADIANS(L8)) + (E8 - W8) * SIN(RADIANS(L8)))) * SIN(RADIANS(K8)) + (F8 - X8) * COS(RADIANS(K8)) + X8, IF(U8 = 4, (F8 + X8) - Y8 * (1 - COS(RADIANS(K8))), IF(U8 = 5, F8 - Y8 * (1 - COS(RADIANS(K8))), IF(U8 = 6, (F8 + X8) - Y8 * SIN(RADIANS(Config!$H$18)) * SIN(RADIANS(Config!$H$18)) * (1 - COS(RADIANS(K8))), COS(RADIANS(K8)) * (F8 - X8) + SIN(RADIANS(K8)) * ( Config!$C$15 * (-(D8 - V8) * SIN(RADIANS(L8)) + (E8 - W8) * COS(RADIANS(L8))) - Config!$C$16 * ((D8 - V8) * COS(RADIANS(L8)) + (E8 - W8) * SIN(RADIANS(L8))) ) + (1 - COS(RADIANS(K8))) * ( ((D8 - V8) * COS(RADIANS(L8)) + (E8 - W8) * SIN(RADIANS(L8))) * Config!$C$15 + (-(D8 - V8) * SIN(RADIANS(L8)) + (E8 - W8) * COS(RADIANS(L8))) * Config!$C$16 + (F8 - X8) * Config!$C$17 ) * Config!$C$17 + X8 ) ) ) ) ) ) ) -> 0 | R8: =IF(I8="","", IF(OR( K8 < IF(Config!$C$4=1,Config!$C$34, IF(Config!$C$4=2,Config!$D$34, IF(Config!$C$4=3,Config!$E$34, IF(Config!$C$4=4,Config!$F$34, IF(Config!$C$4=5,Config!$G$34, IF(Config!$C$4=6,Config!$H$34,Config!$I$34) ) ) ) ) ), K8 > IF(Config!$C$4=1,Config!$C$35, IF(Config!$C$4=2,Config!$D$35, IF(Config!$C$4=3,Config!$E$35, IF(Config!$C$4=4,Config!$F$35, IF(Config!$C$4=5,Config!$G$35, IF(Config!$C$4=6,Config!$H$35,Config!$I$35) ) ) ) ) ) ), "⚠ OUT OF RANGE", "OK" ) ) -> OK | S8: =IF(I8="","", IF(OR( L8 < IF(Config!$C$4=1,Config!$C$36, IF(Config!$C$4=2,Config!$D$36, IF(Config!$C$4=3,Config!$E$36, IF(Config!$C$4=4,Config!$F$36, IF(Config!$C$4=5,Config!$G$36, IF(Config!$C$4=6,Config!$H$36,Config!$I$36) ) ) ) ) ), L8 > IF(Config!$C$4=1,Config!$C$37, IF(Config!$C$4=2,Config!$D$37, IF(Config!$C$4=3,Config!$E$37, IF(Config!$C$4=4,Config!$F$37, IF(Config!$C$4=5,Config!$G$37, IF(Config!$C$4=6,Config!$H$37,Config!$I$37) ) ) ) ) ) ), "⚠ OUT OF RANGE", "OK" ) ) -> OK | U8: =Config!$C$4 -> 1 | V8: =IF(U8=1, Config!$C$27, IF(U8=2, Config!$D$27, IF(U8=3, Config!$E$27, IF(U8=4, Config!$F$27, IF(U8=5, Config!$G$27, IF(U8=6, Config!$H$27, Config!$I$27 ) ) ) ) ) ) -> 0 | W8: =IF(U8=1, Config!$C$28, IF(U8=2, Config!$D$28, IF(U8=3, Config!$E$28, IF(U8=4, Config!$F$28, IF(U8=5, Config!$G$28, IF(U8=6, Config!$H$28, Config!$I$28 ) ) ) ) ) ) -> 0 | X8: =IF(U8=1, Config!$C$29, IF(U8=2, Config!$D$29, IF(U8=3, Config!$E$29, IF(U8=4, Config!$F$29, IF(U8=5, Config!$G$29, IF(U8=6, Config!$H$29, Config!$I$29 ) ) ) ) ) ) -> 0 | Y8: =IF(U8=1, Config!$C$30, IF(U8=2, Config!$D$30, IF(U8=3, Config!$E$30, IF(U8=4, Config!$F$30, IF(U8=5, Config!$G$30, IF(U8=6, Config!$H$30, Config!$I$30 ) ) ) ) ) ) -> 0 | AA8: =IF(I8="","", IF(U8<=2, IF(AND(G8=0,H8=0), 0, -K8), IF(U8=3, IF(AND(G8=0,H8=0), 0, -K8), IF(U8=4, IF(K8>=0, 180-K8, -180-K8), IF(U8=5, "N/A", IF(U8=6, IF(AND(G8=0,H8=0), 0, -K8), "N/A" ) ) ) ) ) ) -> 4.1325531 | AB8: =IF(I8="","", IF(U8<=2, IF(AND(G8=0,H8=0), 0, IF(L8<=0, L8+180, L8-180) ), IF(U8=3, IF(AND(G8=0,H8=0), 0, IF(L8<=0, L8+180, L8-180) ), IF(U8=4, L8, IF(U8=5, "N/A", IF(U8=6, IF(AND(G8=0,H8=0), 0, IF(L8<=0, L8+180, L8-180) ), "N/A" ) ) ) ) ) ) -> 43.013331 | AD8: =IF(I8="","", IF(Config!$C$51=1, D8, IF(U8<=2, (D8 - V8)*COS(RADIANS(AB8)) + (E8 - W8)*SIN(RADIANS(AB8)) + V8, IF(U8=3, ((D8 - V8)*COS(RADIANS(AB8)) + (E8 - W8)*SIN(RADIANS(AB8)))*COS(RADIANS(AA8)) + (F8 - X8)*SIN(RADIANS(AA8)) + V8, IF(U8=4, (D8*COS(RADIANS(AB8)) + E8*SIN(RADIANS(AB8)) + V8) + Y8*SIN(RADIANS(AA8)), IF(U8=5, D8 + Y8*SIN(RADIANS(AA8))*COS(RADIANS(AB8)), IF(U8=6, (D8*COS(RADIANS(AB8)) + E8*SIN(RADIANS(AB8)) + V8) + Y8*SIN(RADIANS(AA8))*SIN(RADIANS(Config!$H$18)), COS(RADIANS(AA8)) * (((D8 - V8)*COS(RADIANS(AB8)) + (E8 - W8)*SIN(RADIANS(AB8)))) + SIN(RADIANS(AA8)) * ( Config!$C$16*(F8 - X8) - Config!$C$17*(-(D8 - V8)*SIN(RADIANS(AB8)) + (E8 - W8)*COS(RADIANS(AB8))) ) + (1 - COS(RADIANS(AA8))) * ( ((D8 - V8)*COS(RADIANS(AB8)) + (E8 - W8)*SIN(RADIANS(AB8)))*Config!$C$15 + (-(D8 - V8)*SIN(RADIANS(AB8)) + (E8 - W8)*COS(RADIANS(AB8)))*Config!$C$16 + (F8 - X8)*Config!$C$17 ) * Config!$C$15 + V8 ) ) ) ) ) ) ) -> 0 | AE8: =IF(I8="","", IF(Config!$C$51=1, E8, IF(U8 <= 2, (-(D8 - V8) * SIN(RADIANS(AB8)) + (E8 - W8) * COS(RADIANS(AB8))) * COS(RADIANS(AA8)) + (F8 - X8) * SIN(RADIANS(AA8)) + W8, IF(U8 = 3, (-(D8 - V8) * SIN(RADIANS(AB8)) + (E8 - W8) * COS(RADIANS(AB8))) + W8, IF(U8 = 4, -(D8) * SIN(RADIANS(AB8)) + (E8) * COS(RADIANS(AB8)) + W8, IF(U8 = 5, E8 + Y8 * SIN(RADIANS(AA8)) * SIN(RADIANS(AB8)), IF(U8 = 6, (-(D8) * SIN(RADIANS(AB8)) + (E8) * COS(RADIANS(AB8)) + W8) + Y8 * (1 - COS(RADIANS(AA8))) * SIN(RADIANS(Config!$H$18)) * COS(RADIANS(Config!$H$18)), COS(RADIANS(AA8)) * (-(D8 - V8) * SIN(RADIANS(AB8)) + (E8 - W8) * COS(RADIANS(AB8))) + SIN(RADIANS(AA8)) * ( Config!$C$17 * ((D8 - V8) * COS(RADIANS(AB8)) + (E8 - W8) * SIN(RADIANS(AB8))) - Config!$C$15 * (F8 - X8) ) + (1 - COS(RADIANS(AA8))) * ( ((D8 - V8) * COS(RADIANS(AB8)) + (E8 - W8) * SIN(RADIANS(AB8))) * Config!$C$15 + (-(D8 - V8) * SIN(RADIANS(AB8)) + (E8 - W8) * COS(RADIANS(AB8))) * Config!$C$16 + (F8 - X8) * Config!$C$17 ) * Config!$C$16 + W8 ) ) ) ) ) ) ) -> 0 | AF8: =IF(I8="","", IF(Config!$C$51=1, F8, IF(U8 <= 2, -((-(D8 - V8) * SIN(RADIANS(AB8)) + (E8 - W8) * COS(RADIANS(AB8)))) * SIN(RADIANS(AA8)) + (F8 - X8) * COS(RADIANS(AA8)) + X8, IF(U8 = 3, -(((D8 - V8) * COS(RADIANS(AB8)) + (E8 - W8) * SIN(RADIANS(AB8)))) * SIN(RADIANS(AA8)) + (F8 - X8) * COS(RADIANS(AA8)) + X8, IF(U8 = 4, (F8 + X8) - Y8 * (1 - COS(RADIANS(AA8))), IF(U8 = 5, F8 - Y8 * (1 - COS(RADIANS(AA8))), IF(U8 = 6, (F8 + X8) - Y8 * SIN(RADIANS(Config!$H$18)) * SIN(RADIANS(Config!$H$18)) * (1 - COS(RADIANS(AA8))), COS(RADIANS(AA8)) * (F8 - X8) + SIN(RADIANS(AA8)) * ( Config!$C$15 * (-(D8 - V8) * SIN(RADIANS(AB8)) + (E8 - W8) * COS(RADIANS(AB8))) - Config!$C$16 * ((D8 - V8) * COS(RADIANS(AB8)) + (E8 - W8) * SIN(RADIANS(AB8))) ) + (1 - COS(RADIANS(AA8))) * ( ((D8 - V8) * COS(RADIANS(AB8)) + (E8 - W8) * SIN(RADIANS(AB8))) * Config!$C$15 + (-(D8 - V8) * SIN(RADIANS(AB8)) + (E8 - W8) * COS(RADIANS(AB8))) * Config!$C$16 + (F8 - X8) * Config!$C$17 ) * Config!$C$17 + X8 ) ) ) ) ) ) ) -> 0 | AH8: =IF(I8="","", IF(OR(AA8="N/A", AA8=""), "N/A", IF(OR( AA8 < IF(Config!$C$4=1,Config!$C$34, IF(Config!$C$4=2,Config!$D$34, IF(Config!$C$4=3,Config!$E$34, IF(Config!$C$4=4,Config!$F$34, IF(Config!$C$4=5,Config!$G$34, IF(Config!$C$4=6,Config!$H$34,Config!$I$34) ) ) ) ) ), AA8 > IF(Config!$C$4=1,Config!$C$35, IF(Config!$C$4=2,Config!$D$35, IF(Config!$C$4=3,Config!$E$35, IF(Config!$C$4=4,Config!$F$35, IF(Config!$C$4=5,Config!$G$35, IF(Config!$C$4=6,Config!$H$35,Config!$I$35) ) ) ) ) ) ), "⚠ OUT OF RANGE", "OK" ) ) ) -> OK | AI8: =IF(I8="","", IF(OR(AB8="N/A", AB8=""), "N/A", IF(OR( AB8 < IF(Config!$C$4=1,Config!$C$36, IF(Config!$C$4=2,Config!$D$36, IF(Config!$C$4=3,Config!$E$36, IF(Config!$C$4=4,Config!$F$36, IF(Config!$C$4=5,Config!$G$36, IF(Config!$C$4=6,Config!$H$36,Config!$I$36) ) ) ) ) ), AB8 > IF(Config!$C$4=1,Config!$C$37, IF(Config!$C$4=2,Config!$D$37, IF(Config!$C$4=3,Config!$E$37, IF(Config!$C$4=4,Config!$F$37, IF(Config!$C$4=5,Config!$G$37, IF(Config!$C$4=6,Config!$H$37,Config!$I$37) ) ) ) ) ) ), "⚠ OUT OF RANGE", "OK" ) ) ) -> OK
